<?xml version="1.0"?>
<robot xmlns:xacro="http://www.ros.org/wiki/xacro">
    <xacro:include filename="inertial_macros.xacro" />

    <material name="white">
        <color rgba="1 1 1 1" />
    </material>

    <material name="orange">
        <color rgba="1 0.3 0.1 1" />
    </material>

    <material name="blue">
        <color rgba="0.2 0.2 1 1" />
    </material>

    <material name="black">
        <color rgba="0 0 0 1" />
    </material>

    <material name="dark_grey">
        <color rgba="0.3 0.3 0.3 1" />
    </material>

    <!-- CHASSIS LINK -->

    <joint name="chassis_joint" type="fixed">
        <parent link="base_link" />
        <child link="chassis" />
        <origin xyz="-0.25 0 0.1" />
    </joint>

    <link name="chassis">
        <visual>
            <origin xyz="0.0 0 0" rpy="0 0 0" />
            <geometry>
                <box size="0.5 0.4 0.02" />
            </geometry>
            <material name="white" />
        </visual>
        <xacro:inertial_box mass="0.5" x="0.5" y="0.4" z="0.02">
            <origin xyz="0 0 0" rpy="0 0 0" />
        </xacro:inertial_box>
        <collision>
            <origin xyz="0 0 0"/>
            <geometry>
                <box size="0.5 0.4 0.02"/>
            </geometry>
        </collision>
    </link>

    <gazebo reference="chassis">
        <material>Gazebo/Orange</material>
    </gazebo>

    <!-- LEFT WHEEL LINK -->

    <joint name="left_wheel_joint" type="continuous">
        <parent link="base_link" />
        <child link="left_wheel" />
        <origin xyz="0 0.2 0" rpy="-${pi/2} 0 0" />
        <axis xyz="0 0 1" />
    </joint>

    <link name="left_wheel">
        <visual>
            <geometry>
                <cylinder length="0.055" radius="0.085" />
            </geometry>
            <material name="dark_grey" />
        </visual>
        <xacro:inertial_cylinder mass="0.1" length="0.055" radius="0.085">
            <origin xyz="0 0 0" rpy="0 0 0" />
        </xacro:inertial_cylinder>
        <collision>
            <geometry>
                <cylinder length="0.055" radius="0.085" />
            </geometry>
        </collision>   
    </link>

    <gazebo reference="left_wheel">
        <material>Gazebo/Blue</material>
    </gazebo>

    <joint name="right_wheel_joint" type="continuous">
        <parent link="base_link" />
        <child link="right_wheel" />
        <origin xyz="0 -0.2 0" rpy="${pi/2} 0 0" />
        <axis xyz="0 0 -1" />
    </joint>

    <!-- RIGHT WHEEL LINK -->

    <link name="right_wheel">
        <visual>
            <geometry>
                <cylinder length="0.055" radius="0.085" />
            </geometry>
            <material name="dark_grey" />
        </visual>
        <xacro:inertial_cylinder mass="0.1" length="0.055" radius="0.085">
            <origin xyz="0 0 0" rpy="0 0 0" />
        </xacro:inertial_cylinder>
        <collision>
            <geometry>
                <cylinder length="0.055" radius="0.085" />
            </geometry>
        </collision>   
    </link>

    <gazebo reference="right_wheel">
        <material>Gazebo/Blue</material>
    </gazebo>

     <!-- CASTER WHEELS LINK -->

    <joint name="left_caster_wheel_joint" type="fixed">
        <parent link="base_link" />
        <child link="left_caster_wheel" />
        <origin xyz="-0.5 -0.2 0" rpy="0 0 0" />
    </joint>

    <link name="left_caster_wheel">
        <visual>
            <geometry>
                <sphere radius="0.085" />
            </geometry>
            <material name="orange" />
        </visual>
        <xacro:inertial_sphere mass="0.1" radius="0.085">
            <origin xyz="0 0 0" rpy="0 0 0" />
        </xacro:inertial_sphere>
        <collision>
            <geometry>
                <sphere radius="0.085"/>
            </geometry>
        </collision>
    </link>

    <gazebo reference="left_caster_wheel">
        <material>Gazebo/White</material>
        <mu1 value="0.001" />
        <mu2 value="0.001" />
    </gazebo>

    <joint name="right_caster_wheel_joint" type="fixed">
        <parent link="base_link" />
        <child link="right_caster_wheel" />
        <origin xyz="-0.5 0.2 0" rpy="0 0 0" />
    </joint>

    <link name="right_caster_wheel">
        <visual>
            <geometry>
                <sphere radius="0.085" />
            </geometry>
            <material name="blue" />
        </visual>
        <xacro:inertial_sphere mass="0.1" radius="0.085">
            <origin xyz="0 0 0" rpy="0 0 0" />
        </xacro:inertial_sphere>
        <collision>
            <geometry>
                <sphere radius="0.085"/>
            </geometry>
        </collision>
    </link>

    <gazebo reference="right_caster_wheel">
        <material>Gazebo/White</material>
        <mu1 value="0.001" />
        <mu2 value="0.001" />
    </gazebo>
</robot>